[2023-01-04 14:59:51] [INFO    ] discord.client: logging in using static token
[2023-01-04 15:00:02] [INFO    ] discord.gateway: Shard ID None has connected to Gateway (Session ID: 5f3834e6897048ad9445e6ac713c4725).
[2023-01-04 15:00:54] [ERROR   ] discord.ui.view: Ignoring exception in view <select_view timeout=180 children=1> for item <job_select placeholder='select your job' min_values=1 max_values=1 disabled=False options=[<SelectOption label='miner' value='miner' description='a career that can get lot of jeweris' emoji=<PartialEmoji animated=False name='‚õèÔ∏è' id=None> default=False>, <SelectOption label='farmer' value='farmer' description='a career that can grow foods' emoji=<PartialEmoji animated=False name='ü•¶' id=None> default=False>, <SelectOption label='smith' value='smith' description='a career that can make tools and weapons' emoji=<PartialEmoji animated=False name='‚öíÔ∏è' id=None> default=False>, <SelectOption label='hunter' value='hunter' description='a career that can get meats from nature' emoji=<PartialEmoji animated=False name='üèπ' id=None> default=False>]>
Traceback (most recent call last):
  File "/usr/local/lib/python3.9/dist-packages/discord/ui/view.py", line 425, in _scheduled_task
    await item.callback(interaction)
  File "/var/www/html/bot/rat.py", line 146, in callback
    await interaction.response.send_message(f"{user.name} select {self.values[0]} as job",ephemeral=True)
  File "/usr/local/lib/python3.9/dist-packages/discord/interactions.py", line 769, in send_message
    await adapter.create_interaction_response(
  File "/usr/local/lib/python3.9/dist-packages/discord/webhook/async_.py", line 218, in request
    raise NotFound(response, data)
discord.errors.NotFound: 404 Not Found (error code: 10062): Unknown interaction
[2023-01-04 15:01:26] [ERROR   ] discord.app_commands.tree: Ignoring exception in command 'Â∑•‰Ωú'
Traceback (most recent call last):
  File "/usr/local/lib/python3.9/dist-packages/discord/app_commands/commands.py", line 862, in _do_call
    return await self._callback(interaction, **params)  # type: ignore
  File "/var/www/html/bot/rat.py", line 178, in self
    await interaction.response.send_message(f"work,{user.name},100\n",ephemeral=True)
  File "/usr/local/lib/python3.9/dist-packages/discord/interactions.py", line 769, in send_message
    await adapter.create_interaction_response(
  File "/usr/local/lib/python3.9/dist-packages/discord/webhook/async_.py", line 218, in request
    raise NotFound(response, data)
discord.errors.NotFound: 404 Not Found (error code: 10062): Unknown interaction

The above exception was the direct cause of the following exception:

Traceback (most recent call last):
  File "/usr/local/lib/python3.9/dist-packages/discord/app_commands/tree.py", line 1242, in _call
    await command._invoke_with_namespace(interaction, namespace)
  File "/usr/local/lib/python3.9/dist-packages/discord/app_commands/commands.py", line 887, in _invoke_with_namespace
    return await self._do_call(interaction, transformed_values)
  File "/usr/local/lib/python3.9/dist-packages/discord/app_commands/commands.py", line 880, in _do_call
    raise CommandInvokeError(self, e) from e
discord.app_commands.errors.CommandInvokeError: Command 'Â∑•‰Ωú' raised an exception: NotFound: 404 Not Found (error code: 10062): Unknown interaction
[2023-01-04 15:01:51] [ERROR   ] discord.app_commands.tree: Ignoring exception in command 'Êü•Ë©¢Ê©üÂô®‰∫∫Á¥ÄÈåÑ'
Traceback (most recent call last):
  File "/usr/local/lib/python3.9/dist-packages/discord/app_commands/commands.py", line 862, in _do_call
    return await self._callback(interaction, **params)  # type: ignore
  File "/var/www/html/bot/rat.py", line 165, in self
    await i.response.send_message(f"{history.show()}")
  File "/usr/local/lib/python3.9/dist-packages/discord/interactions.py", line 769, in send_message
    await adapter.create_interaction_response(
  File "/usr/local/lib/python3.9/dist-packages/discord/webhook/async_.py", line 218, in request
    raise NotFound(response, data)
discord.errors.NotFound: 404 Not Found (error code: 10062): Unknown interaction

The above exception was the direct cause of the following exception:

Traceback (most recent call last):
  File "/usr/local/lib/python3.9/dist-packages/discord/app_commands/tree.py", line 1242, in _call
    await command._invoke_with_namespace(interaction, namespace)
  File "/usr/local/lib/python3.9/dist-packages/discord/app_commands/commands.py", line 887, in _invoke_with_namespace
    return await self._do_call(interaction, transformed_values)
  File "/usr/local/lib/python3.9/dist-packages/discord/app_commands/commands.py", line 880, in _do_call
    raise CommandInvokeError(self, e) from e
discord.app_commands.errors.CommandInvokeError: Command 'Êü•Ë©¢Ê©üÂô®‰∫∫Á¥ÄÈåÑ' raised an exception: NotFound: 404 Not Found (error code: 10062): Unknown interaction
[2023-01-04 15:02:28] [ERROR   ] discord.app_commands.tree: Ignoring exception in command 'Êü•Ë©¢Ê©üÂô®‰∫∫ÊúçÂãô‰º∫ÊúçÂô®'
Traceback (most recent call last):
  File "/usr/local/lib/python3.9/dist-packages/discord/app_commands/commands.py", line 862, in _do_call
    return await self._callback(interaction, **params)  # type: ignore
  File "/var/www/html/bot/rat.py", line 159, in self
    await i.response.send_message(f"{show}")
  File "/usr/local/lib/python3.9/dist-packages/discord/interactions.py", line 769, in send_message
    await adapter.create_interaction_response(
  File "/usr/local/lib/python3.9/dist-packages/discord/webhook/async_.py", line 218, in request
    raise NotFound(response, data)
discord.errors.NotFound: 404 Not Found (error code: 10062): Unknown interaction

The above exception was the direct cause of the following exception:

Traceback (most recent call last):
  File "/usr/local/lib/python3.9/dist-packages/discord/app_commands/tree.py", line 1242, in _call
    await command._invoke_with_namespace(interaction, namespace)
  File "/usr/local/lib/python3.9/dist-packages/discord/app_commands/commands.py", line 887, in _invoke_with_namespace
    return await self._do_call(interaction, transformed_values)
  File "/usr/local/lib/python3.9/dist-packages/discord/app_commands/commands.py", line 880, in _do_call
    raise CommandInvokeError(self, e) from e
discord.app_commands.errors.CommandInvokeError: Command 'Êü•Ë©¢Ê©üÂô®‰∫∫ÊúçÂãô‰º∫ÊúçÂô®' raised an exception: NotFound: 404 Not Found (error code: 10062): Unknown interaction
[2023-01-04 15:02:55] [ERROR   ] discord.app_commands.tree: Ignoring exception in command 'close'
Traceback (most recent call last):
  File "/usr/local/lib/python3.9/dist-packages/discord/app_commands/commands.py", line 862, in _do_call
    return await self._callback(interaction, **params)  # type: ignore
  File "/var/www/html/bot/rat.py", line 170, in self
    await interaction.response.send_message(f"turing off rat .....")
  File "/usr/local/lib/python3.9/dist-packages/discord/interactions.py", line 769, in send_message
    await adapter.create_interaction_response(
  File "/usr/local/lib/python3.9/dist-packages/discord/webhook/async_.py", line 218, in request
    raise NotFound(response, data)
discord.errors.NotFound: 404 Not Found (error code: 10062): Unknown interaction

The above exception was the direct cause of the following exception:

Traceback (most recent call last):
  File "/usr/local/lib/python3.9/dist-packages/discord/app_commands/tree.py", line 1242, in _call
    await command._invoke_with_namespace(interaction, namespace)
  File "/usr/local/lib/python3.9/dist-packages/discord/app_commands/commands.py", line 887, in _invoke_with_namespace
    return await self._do_call(interaction, transformed_values)
  File "/usr/local/lib/python3.9/dist-packages/discord/app_commands/commands.py", line 880, in _do_call
    raise CommandInvokeError(self, e) from e
discord.app_commands.errors.CommandInvokeError: Command 'close' raised an exception: NotFound: 404 Not Found (error code: 10062): Unknown interaction
